<?xml version="1.0" encoding="utf-8"?>
<!-- This URDF was automatically created by SolidWorks to URDF Exporter! Originally created by Stephen Brawner (brawner@gmail.com) 
     Commit Version: 1.5.1-0-g916b5db  Build Version: 1.5.7152.31018
     For more information, please see http://wiki.ros.org/sw_urdf_exporter -->
<robot name="mecanum_car">


  <!-- Gazebo -->

  <gazebo>
    <plugin name="gazebo_ros_control" filename="libgazebo_ros_control.so">
      <robotNamespace>/mecanum_car</robotNamespace>
    </plugin>
  </gazebo>


  <gazebo reference="base_link">
    <kp>100000.0</kp>
    <kd>100.0</kd>
    <mu1>1.5</mu1>
    <mu2>1.5</mu2>
    <fdir1>1 0 0</fdir1>
    <maxVel>1.0</maxVel>
    <minDepth>0.001</minDepth>
    <material>Gazebo/Blue</material>
  </gazebo>



  <gazebo reference="link_left_forward">
    <kp>100000.0</kp>
    <kd>100.0</kd>
    <mu1>1.5</mu1>
    <mu2>1.5</mu2>
    <fdir1>1 0 0</fdir1>
    <maxVel>1.0</maxVel>
    <minDepth>0.001</minDepth>
    <material>Gazebo/Yellow</material>
  </gazebo>



  <gazebo reference="link_right_forward">
    <kp>100000.0</kp>
    <kd>100.0</kd>
    <mu1>1.5</mu1>
    <mu2>1.5</mu2>
    <fdir1>1 0 0</fdir1>
    <maxVel>1.0</maxVel>
    <minDepth>0.001</minDepth>
    <material>Gazebo/Yellow</material>
  </gazebo>



  <gazebo reference="link_left_back">
    <kp>100000.0</kp>
    <kd>100.0</kd>
    <mu1>1.5</mu1>
    <mu2>1.5</mu2>
    <fdir1>1 0 0</fdir1>
    <maxVel>1.0</maxVel>
    <minDepth>0.001</minDepth>
    <material>Gazebo/Yellow</material>
  </gazebo>



  <gazebo reference="link_right_back">
    <kp>100000.0</kp>
    <kd>100.0</kd>
    <mu1>1.5</mu1>
    <mu2>1.5</mu2>
    <fdir1>1 0 0</fdir1>
    <maxVel>1.0</maxVel>
    <minDepth>0.001</minDepth>
    <material>Gazebo/Yellow</material>
  </gazebo>



  <gazebo reference="link_rplidarA1">
    <kp>100000.0</kp>
    <kd>100.0</kd>
    <mu1>1.5</mu1>
    <mu2>1.5</mu2>
    <fdir1>1 0 0</fdir1>
    <maxVel>1.0</maxVel>
    <minDepth>0.001</minDepth>
    <material>Gazebo/Gray</material>
  </gazebo>


<!-- Base footprint -->

  <link name="base_footprint"></link>

  <joint name="joint_base_footprint" type="fixed">
    <parent link="base_footprint"/>
    <child link="base_link"/>
    <origin xyz="0.0 0.0 0.037" rpy="0.0 0.0 0.0"/>
  </joint>



  <link name="base_link">
    <inertial>
      <origin xyz="-5.1457E-09 5.1488E-09 0.0011571" rpy="0 0 0" />
      <mass value="0.20851" />
      <inertia ixx="0.00014409" ixy="1.2229E-09" ixz="-1.3529E-11" iyy="0.000526" iyz="1.6049E-11" izz="0.00065951" />
    </inertial>
    <visual>
      <origin xyz="0 0 0" rpy="0 0 0" />
      <geometry>
        <mesh filename="package://mecanum_description/meshes/base_link.STL" />
      </geometry>
      <material name="blue">
        <color rgba="0.0 0.0 0.8 1.0"/>
      </material>
    </visual>
    <collision>
      <origin xyz="0 0 0" rpy="0 0 0" />
      <geometry>
        <mesh filename="package://mecanum_description/meshes/base_link.STL" />
      </geometry>
    </collision>
  </link>






  <link name="link_left_forward">
    <inertial>
      <origin xyz="4.9405E-14 5.1716E-14 -0.016049" rpy="0 0 0" />
      <mass value="0.053624" />
      <inertia ixx="5.7347E-06" ixy="3.7019E-15" ixz="4.285E-18" iyy="5.734E-06" iyz="-6.0498E-19" izz="6.5431E-06" />
    </inertial>
    <visual>
      <origin xyz="0 0 0" rpy="0 0 0" />
      <geometry>
        <mesh filename="package://mecanum_description/meshes/link_left_forward.STL" />
      </geometry>
      <material name="brightyellow">
        <color rgba="1.0 0.9921568627450981 0.00392156862745098 1.0" />
      </material>
    </visual>
    <collision>
      <origin xyz="0 0 0" rpy="0 0 0" />
      <geometry>
        <mesh filename="package://mecanum_description/meshes/link_left_forward.STL" />
      </geometry>
    </collision>
  </link>
  <joint name="joint_left_forward" type="continuous">
    <origin xyz="0.06425 0.092237 -0.012873" rpy="-1.5708 0 0" />
    <parent link="base_link" />
    <child link="link_left_forward" />
    <axis xyz="0 0 1" />
    <dynamics damping="0.1" friction="0.1" />
  </joint>
  <link name="link_right_forward">
    <inertial>
      <origin xyz="2.4092E-14 1.7994E-14 0.016049" rpy="0 0 0" />
      <mass value="0.053624" />
      <inertia ixx="5.7347E-06" ixy="4.1621E-15" ixz="-4.3954E-18" iyy="5.734E-06" iyz="2.2808E-19" izz="6.5431E-06" />
    </inertial>
    <visual>
      <origin xyz="0 0 0" rpy="0 0 0" />
      <geometry>
        <mesh filename="package://mecanum_description/meshes/link_right_forward.STL" />
      </geometry>
      <material name="brightyellow">
        <color rgba="1.0 0.9921568627450981 0.00392156862745098 1.0" />
      </material>
    </visual>
    <collision>
      <origin xyz="0 0 0" rpy="0 0 0" />
      <geometry>
        <mesh filename="package://mecanum_description/meshes/link_right_forward.STL" />
      </geometry>
    </collision>
  </link>
  <joint name="joint_right_forward" type="continuous">
    <origin xyz="0.06425 -0.092237 -0.012873" rpy="-1.5708 0 0" />
    <parent link="base_link" />
    <child link="link_right_forward" />
    <axis xyz="0 0 1" />
    <dynamics damping="0.1" friction="0.1" />
  </joint>
  <link name="link_left_back">
    <inertial>
      <origin xyz="5.0265E-14 5.0931E-14 -0.016049" rpy="0 0 0" />
      <mass value="0.053624" />
      <inertia ixx="5.7347E-06" ixy="3.7079E-15" ixz="-1.2646E-18" iyy="5.734E-06" iyz="1.4228E-18" izz="6.5431E-06" />
    </inertial>
    <visual>
      <origin xyz="0 0 0" rpy="0 0 0" />
      <geometry>
        <mesh filename="package://mecanum_description/meshes/link_left_back.STL" />
      </geometry>
      <material name="brightyellow">
        <color rgba="1.0 0.9921568627450981 0.00392156862745098 1.0" />
      </material>
    </visual>
    <collision>
      <origin xyz="0 0 0" rpy="0 0 0" />
      <geometry>
        <mesh filename="package://mecanum_description/meshes/link_left_back.STL" />
      </geometry>
    </collision>
  </link>
  <joint name="joint_left_back" type="continuous">
    <origin xyz="-0.06425 0.092237 -0.012873" rpy="-1.5708 0 0" />
    <parent link="base_link" />
    <child link="link_left_back" />
    <axis xyz="0 0 1" />
    <dynamics damping="0.1" friction="0.1" />
  </joint>
  <link name="link_right_back">
    <inertial>
      <origin xyz="2.3259E-14 1.7262E-14 0.016049" rpy="0 0 0" />
      <mass value="0.053624" />
      <inertia ixx="5.7347E-06" ixy="4.1609E-15" ixz="1.6088E-18" iyy="5.734E-06" iyz="-7.2378E-18" izz="6.5431E-06" />
    </inertial>
    <visual>
      <origin xyz="0 0 0" rpy="0 0 0" />
      <geometry>
        <mesh filename="package://mecanum_description/meshes/link_right_back.STL" />
      </geometry>
      <material name="brightyellow">
        <color rgba="1.0 0.9921568627450981 0.00392156862745098 1.0" />
      </material>
    </visual>
    <collision>
      <origin xyz="0 0 0" rpy="0 0 0" />
      <geometry>
        <mesh filename="package://mecanum_description/meshes/link_right_back.STL" />
      </geometry>
    </collision>
  </link>
  <joint name="joint_right_back" type="continuous">
    <origin xyz="-0.06425 -0.092237 -0.012873" rpy="-1.5708 0 0" />
    <parent link="base_link" />
    <child link="link_right_back" />
    <axis xyz="0 0 1" />
    <dynamics damping="0.1" friction="0.1" />
  </joint>
  <link name="link_rplidarA1">
    <inertial>
      <origin xyz="-0.0057842 -0.0004951 0.0039383" rpy="0 0 0" />
      <mass value="0.14299" />
      <inertia ixx="4.6277E-05" ixy="-8.5349E-07" ixz="-3.6217E-06" iyy="7.3474E-05" iyz="2.0431E-07" izz="0.00010796" />
    </inertial>
    <visual>
      <origin xyz="0 0 0" rpy="0 0 0" />
      <geometry>
        <mesh filename="package://mecanum_description/meshes/link_rplidarA1.STL" />
      </geometry>
      <material name="grey">
        <color rgba="0.2 0.2 0.2 1.0"/>
      </material>

    </visual>
    <collision>
      <origin xyz="0 0 0" rpy="0 0 0" />
      <geometry>
        <mesh filename="package://mecanum_description/meshes/link_rplidarA1.STL" />
      </geometry>
    </collision>
  </link>
  <joint name="joint_rplidarA1" type="fixed">
    <origin xyz="0.080522 0.00057222 0.0631" rpy="0 0 0" />
    <parent link="base_link" />
    <child link="link_rplidarA1" />
    <axis xyz="0 0 1" />
    <dynamics damping="0.1" friction="0.1" />
  </joint>


</robot>